<?xml version="1.0"?>
<robot name="five_dof_arm">

  <!-- ================= LINKS ================= -->

  <link name="base_link"/>
  <link name="link1"/>
  <link name="link2"/>
  <link name="link3"/>
  <link name="link4"/>
  <link name="link5"/>
  <link name="tool_link"/>

  <!-- ================= JOINT 1 ================= -->
  <!-- Base Yaw -->

  <joint name="joint1_base_yaw" type="revolute">
    <parent link="base_link"/>
    <child link="link1"/>
    <origin xyz="0 0 0.122" rpy="0 0 0"/>
    <axis xyz="0 0 1"/>
    <limit lower="-3.14" upper="3.14" effort="10" velocity="2"/>
  </joint>

  <!-- ================= JOINT 2 ================= -->
  <!-- Shoulder Pitch -->

  <!-- zero_offset_degrees = -90 means:
       when the app angle is 0°, the physical joint is rotated -90° from the URDF's zero,
       so visually "straight up" can correspond to 0° in the UI. -->
  <joint name="joint2_shoulder_pitch" type="revolute" zero_offset_degrees="-90">
    <parent link="link1"/>
    <child link="link2"/>
    <origin xyz="0 0 0" rpy="0 0 0"/>
    <axis xyz="0 1 0"/>
    <limit lower="-1.57" upper="1.57" effort="10" velocity="2"/>
  </joint>

  <!-- ================= JOINT 3 ================= -->
  <!-- Elbow Pitch -->

  <joint name="joint3_elbow_pitch" type="revolute">
    <parent link="link2"/>
    <child link="link3"/>
    <origin xyz="0.16178 0 0" rpy="0 0 0"/>
    <axis xyz="0 -1 0"/>
    <limit lower="-1.74533" upper="1.74533" effort="10" velocity="2"/>
  </joint>

  <!-- ================= JOINT 4 ================= -->
  <!-- Wrist Roll (inline with forearm) -->

  <joint name="joint4_wrist_roll" type="revolute">
    <parent link="link3"/>
    <child link="link4"/>
    <origin xyz="0.14820 0 0" rpy="0 0 0"/>
    <axis xyz="1 0 0"/>
    <limit lower="-3.14" upper="3.14" effort="5" velocity="3"/>
  </joint>

  <!-- ================= JOINT 5 ================= -->
  <!-- Wrist Pitch -->

  <joint name="joint5_wrist_pitch" type="revolute">
    <parent link="link4"/>
    <child link="link5"/>
    <origin xyz="0.03 0 0" rpy="0 0 0"/>
    <axis xyz="0 1 0"/>
    <limit lower="-1.57" upper="1.57" effort="5" velocity="3"/>
  </joint>

  <!-- ================= TOOL (Fixed) ================= -->

  <joint name="tool_fixed" type="fixed">
    <parent link="link5"/>
    <child link="tool_link"/>
    <origin xyz="0.042 0 0" rpy="0 0 0"/>
  </joint>

</robot>

